[2024-09-04T03:04:08.450+0000] {local_task_job_runner.py:120} INFO - ::group::Pre task execution logs
[2024-09-04T03:04:08.483+0000] {taskinstance.py:2076} INFO - Dependencies all met for dep_context=non-requeueable deps ti=<TaskInstance: import_csv_to_mysql.import_csv_to_mysql manual__2024-09-04T03:04:07.749172+00:00 [queued]>
[2024-09-04T03:04:08.493+0000] {taskinstance.py:2076} INFO - Dependencies all met for dep_context=requeueable deps ti=<TaskInstance: import_csv_to_mysql.import_csv_to_mysql manual__2024-09-04T03:04:07.749172+00:00 [queued]>
[2024-09-04T03:04:08.493+0000] {taskinstance.py:2306} INFO - Starting attempt 1 of 6
[2024-09-04T03:04:08.509+0000] {taskinstance.py:2330} INFO - Executing <Task(PythonOperator): import_csv_to_mysql> on 2024-09-04 03:04:07.749172+00:00
[2024-09-04T03:04:08.516+0000] {logging_mixin.py:188} WARNING - /home/airflow/.local/lib/python3.12/site-packages/airflow/task/task_runner/standard_task_runner.py:62 DeprecationWarning: This process (pid=1835) is multi-threaded, use of fork() may lead to deadlocks in the child.
[2024-09-04T03:04:08.517+0000] {standard_task_runner.py:64} INFO - Started process 1836 to run task
[2024-09-04T03:04:08.516+0000] {standard_task_runner.py:90} INFO - Running: ['airflow', 'tasks', 'run', 'import_csv_to_mysql', 'import_csv_to_mysql', 'manual__2024-09-04T03:04:07.749172+00:00', '--job-id', '26', '--raw', '--subdir', 'DAGS_FOLDER/import_csv_to_mysql_dag.py', '--cfg-path', '/tmp/tmpi_sbrplf']
[2024-09-04T03:04:08.517+0000] {standard_task_runner.py:91} INFO - Job 26: Subtask import_csv_to_mysql
[2024-09-04T03:04:08.532+0000] {logging_mixin.py:188} WARNING - /home/airflow/.local/lib/python3.12/site-packages/airflow/settings.py:195 DeprecationWarning: The sql_alchemy_conn option in [core] has been moved to the sql_alchemy_conn option in [database] - the old setting has been used, but please update your config.
[2024-09-04T03:04:08.566+0000] {task_command.py:426} INFO - Running <TaskInstance: import_csv_to_mysql.import_csv_to_mysql manual__2024-09-04T03:04:07.749172+00:00 [running]> on host f537b9e2448c
[2024-09-04T03:04:08.654+0000] {taskinstance.py:2648} INFO - Exporting env vars: AIRFLOW_CTX_DAG_OWNER='congdat' AIRFLOW_CTX_DAG_ID='import_csv_to_mysql' AIRFLOW_CTX_TASK_ID='import_csv_to_mysql' AIRFLOW_CTX_EXECUTION_DATE='2024-09-04T03:04:07.749172+00:00' AIRFLOW_CTX_TRY_NUMBER='1' AIRFLOW_CTX_DAG_RUN_ID='manual__2024-09-04T03:04:07.749172+00:00'
[2024-09-04T03:04:08.654+0000] {taskinstance.py:430} INFO - ::endgroup::
[2024-09-04T03:04:08.677+0000] {base.py:84} INFO - Using connection ID 'mysql_default' for task execution.
[2024-09-04T03:04:08.683+0000] {taskinstance.py:441} INFO - ::group::Post task execution logs
[2024-09-04T03:04:08.684+0000] {taskinstance.py:2905} ERROR - Task failed with exception
Traceback (most recent call last):
  File "/home/airflow/.local/lib/python3.12/site-packages/airflow/models/taskinstance.py", line 465, in _execute_task
    result = _execute_callable(context=context, **execute_callable_kwargs)
             ^^^^^^^^^^^^^^^^^^^^^^^^^^^^^^^^^^^^^^^^^^^^^^^^^^^^^^^^^^^^^
  File "/home/airflow/.local/lib/python3.12/site-packages/airflow/models/taskinstance.py", line 432, in _execute_callable
    return execute_callable(context=context, **execute_callable_kwargs)
           ^^^^^^^^^^^^^^^^^^^^^^^^^^^^^^^^^^^^^^^^^^^^^^^^^^^^^^^^^^^^
  File "/home/airflow/.local/lib/python3.12/site-packages/airflow/models/baseoperator.py", line 401, in wrapper
    return func(self, *args, **kwargs)
           ^^^^^^^^^^^^^^^^^^^^^^^^^^^
  File "/home/airflow/.local/lib/python3.12/site-packages/airflow/operators/python.py", line 235, in execute
    return_value = self.execute_callable()
                   ^^^^^^^^^^^^^^^^^^^^^^^
  File "/home/airflow/.local/lib/python3.12/site-packages/airflow/operators/python.py", line 252, in execute_callable
    return self.python_callable(*self.op_args, **self.op_kwargs)
           ^^^^^^^^^^^^^^^^^^^^^^^^^^^^^^^^^^^^^^^^^^^^^^^^^^^^^
  File "/opt/airflow/dags/import_csv_to_mysql_dag.py", line 87, in import_csv_to_mysql
    with open(csv_file_path, 'r') as file:
         ^^^^^^^^^^^^^^^^^^^^^^^^
FileNotFoundError: [Errno 2] No such file or directory: 'D:/Intern/Yeucau3/Scheduler/dags/Nhan_vien.csv'
[2024-09-04T03:04:08.696+0000] {taskinstance.py:1206} INFO - Marking task as UP_FOR_RETRY. dag_id=import_csv_to_mysql, task_id=import_csv_to_mysql, run_id=manual__2024-09-04T03:04:07.749172+00:00, execution_date=20240904T030407, start_date=20240904T030408, end_date=20240904T030408
[2024-09-04T03:04:08.708+0000] {standard_task_runner.py:110} ERROR - Failed to execute job 26 for task import_csv_to_mysql ([Errno 2] No such file or directory: 'D:/Intern/Yeucau3/Scheduler/dags/Nhan_vien.csv'; 1836)
[2024-09-04T03:04:08.730+0000] {local_task_job_runner.py:243} INFO - Task exited with return code 1
[2024-09-04T03:04:08.747+0000] {taskinstance.py:3503} INFO - 0 downstream tasks scheduled from follow-on schedule check
[2024-09-04T03:04:08.749+0000] {local_task_job_runner.py:222} INFO - ::endgroup::
